<robot
  name="5DoF-arm-kenny">
  <link
    name="base_link">
    <inertial>
      <origin
        xyz="0.06886 0.1931 -0.17069"
        rpy="0 0 0" />
      <mass
        value="0.11287" />
      <inertia
        ixx="4.8922E-05"
        ixy="-1.4252E-06"
        ixz="1.6743E-06"
        iyy="7.0574E-05"
        iyz="-4.5738E-07"
        izz="4.3857E-05" />
    </inertial>
    <visual>
      <origin
        xyz="0 0 0"
        rpy="0 0 0" />
      <geometry>
        <mesh
          filename="package://5DoF-arm-kenny/meshes/base_link.STL" />
      </geometry>
      <material
        name="">
        <color
          rgba="0 0 0 1" />
      </material>
    </visual>
    <collision>
      <origin
        xyz="0 0 0"
        rpy="0 0 0" />
      <geometry>
        <mesh
          filename="package://5DoF-arm-kenny/meshes/base_link.STL" />
      </geometry>
    </collision>
  </link>
  <link
    name="L1">
    <inertial>
      <origin
        xyz="-7.2164E-16 -0.02855 -0.069607"
        rpy="0 0 0" />
      <mass
        value="0.024964" />
      <inertia
        ixx="6.8484E-05"
        ixy="-4.4893E-19"
        ixz="-7.1151E-20"
        iyy="4.8155E-05"
        iyz="-6.9181E-19"
        izz="2.2861E-05" />
    </inertial>
    <visual>
      <origin
        xyz="0 0 0"
        rpy="0 0 0" />
      <geometry>
        <mesh
          filename="package://5DoF-arm-kenny/meshes/L1.STL" />
      </geometry>
      <material
        name="">
        <color
          rgba="1 1 0 1" />
      </material>
    </visual>
    <collision>
      <origin
        xyz="0 0 0"
        rpy="0 0 0" />
      <geometry>
        <mesh
          filename="package://5DoF-arm-kenny/meshes/L1.STL" />
      </geometry>
    </collision>
  </link>
  <joint
    name="J1"
    type="revolute">
    <origin
      xyz="0.083264 0.11027 0.31677"
      rpy="2.1235E-17 0.51698 -1.877" />
    <parent
      link="base_link" />
    <child
      link="L1" />
    <axis
      xyz="0.95347 -0.30148 0" />
    <limit
      effort="0"
      velocity="0" />
  </joint>
  <link
    name="L2">
    <inertial>
      <origin
        xyz="0.090842 -0.011944 -0.012693"
        rpy="0 0 0" />
      <mass
        value="0.10579" />
      <inertia
        ixx="2.2426E-05"
        ixy="-1.5823E-07"
        ixz="1.2951E-06"
        iyy="0.00047761"
        iyz="-6.1784E-07"
        izz="0.00048493" />
    </inertial>
    <visual>
      <origin
        xyz="0 0 0"
        rpy="0 0 0" />
      <geometry>
        <mesh
          filename="package://5DoF-arm-kenny/meshes/L2.STL" />
      </geometry>
      <material
        name="">
        <color
          rgba="0 1 1 1" />
      </material>
    </visual>
    <collision>
      <origin
        xyz="0 0 0"
        rpy="0 0 0" />
      <geometry>
        <mesh
          filename="package://5DoF-arm-kenny/meshes/L2.STL" />
      </geometry>
    </collision>
  </link>
  <joint
    name="J2"
    type="revolute">
    <origin
      xyz="0.13567 -0.01585 0.064748"
      rpy="-3.1416 0.51184 -3.1416" />
    <parent
      link="L1" />
    <child
      link="L2" />
    <axis
      xyz="0 1 0" />
    <limit
      effort="0"
      velocity="0" />
  </joint>
  <link
    name="L3">
    <inertial>
      <origin
        xyz="-0.018818 -0.01115 0.0037361"
        rpy="0 0 0" />
      <mass
        value="0.0057062" />
      <inertia
        ixx="4.8474E-06"
        ixy="-1.747E-21"
        ixz="2.682E-07"
        iyy="2.3034E-06"
        iyz="3.2756E-22"
        izz="6.7343E-06" />
    </inertial>
    <visual>
      <origin
        xyz="0 0 0"
        rpy="0 0 0" />
      <geometry>
        <mesh
          filename="package://5DoF-arm-kenny/meshes/L3.STL" />
      </geometry>
      <material
        name="">
        <color
          rgba="0.79216 0.81961 0.93333 1" />
      </material>
    </visual>
    <collision>
      <origin
        xyz="0 0 0"
        rpy="0 0 0" />
      <geometry>
        <mesh
          filename="package://5DoF-arm-kenny/meshes/L3.STL" />
      </geometry>
    </collision>
  </link>
  <joint
    name="J3"
    type="revolute">
    <origin
      xyz="0.01 0 -0.01"
      rpy="-1.3697E-17 0.072098 2.6158E-15" />
    <parent
      link="L2" />
    <child
      link="L3" />
    <axis
      xyz="0 1 0" />
    <limit
      effort="0"
      velocity="0" />
  </joint>
</robot>