<robot
  name="5DoF-arm-kenny">
  <link
    name="base_link">
    <inertial>
      <origin
        xyz="0.0909454406425499 -0.13965567381319 0.157171921902302"
        rpy="0 0 0" />
      <mass
        value="0.0432483576430209" />
      <inertia
        ixx="5.09268075478606E-05"
        ixy="2.59188777664549E-21"
        ixz="-1.66744586170117E-23"
        iyy="5.09419397716315E-05"
        iyz="3.25596142315923E-21"
        izz="0.000101803874783028" />
    </inertial>
    <visual>
      <origin
        xyz="0 0 0"
        rpy="0 0 0" />
      <geometry>
        <mesh
          filename="package://5DoF-arm-kenny/meshes/base_link.STL" />
      </geometry>
      <material
        name="">
        <color
          rgba="0.792156862745098 0.819607843137255 0.933333333333333 1" />
      </material>
    </visual>
    <collision>
      <origin
        xyz="0 0 0"
        rpy="0 0 0" />
      <geometry>
        <mesh
          filename="package://5DoF-arm-kenny/meshes/base_link.STL" />
      </geometry>
    </collision>
  </link>
  <link
    name=" link1">
    <inertial>
      <origin
        xyz="0.0305 0.00889748247239139 -0.0202038963244885"
        rpy="0 0 0" />
      <mass
        value="0.0191547172964518" />
      <inertia
        ixx="8.79025148291327E-06"
        ixy="-1.3486857261949E-10"
        ixz="-7.19978005166155E-21"
        iyy="1.55381672632276E-05"
        iyz="-1.38029842216372E-06"
        izz="1.14205522352593E-05" />
    </inertial>
    <visual>
      <origin
        xyz="0 0 0"
        rpy="0 0 0" />
      <geometry>
        <mesh
          filename="package://5DoF-arm-kenny/meshes/ link1.STL" />
      </geometry>
      <material
        name="">
        <color
          rgba="0.752941176470588 0.752941176470588 0.752941176470588 1" />
      </material>
    </visual>
    <collision>
      <origin
        xyz="0 0 0"
        rpy="0 0 0" />
      <geometry>
        <mesh
          filename="package://5DoF-arm-kenny/meshes/ link1.STL" />
      </geometry>
    </collision>
  </link>
  <joint
    name="primera rotacion"
    type="revolute">
    <origin
      xyz="0.11396 -0.095001 0.16267"
      rpy="1.5708 -1.4373E-17 -2.9046" />
    <parent
      link="base_link" />
    <child
      link=" link1" />
    <axis
      xyz="0 0 -1" />
    <limit
      effort="0"
      velocity="0" />
  </joint>
  <link
    name="link2">
    <inertial>
      <origin
        xyz="-0.0196142316595342 -0.0365500000000025 0.067604886102941"
        rpy="0 0 0" />
      <mass
        value="0.0249636399428571" />
      <inertia
        ixx="6.49415256404332E-05"
        ixy="-1.41623908780919E-18"
        ixz="1.22089450266614E-05"
        iyy="4.81551547315452E-05"
        iyz="-7.83505476210228E-21"
        izz="2.64028209000994E-05" />
    </inertial>
    <visual>
      <origin
        xyz="0 0 0"
        rpy="0 0 0" />
      <geometry>
        <mesh
          filename="package://5DoF-arm-kenny/meshes/link2.STL" />
      </geometry>
      <material
        name="">
        <color
          rgba="1 1 0 1" />
      </material>
    </visual>
    <collision>
      <origin
        xyz="0 0 0"
        rpy="0 0 0" />
      <geometry>
        <mesh
          filename="package://5DoF-arm-kenny/meshes/link2.STL" />
      </geometry>
    </collision>
  </link>
  <joint
    name="j1"
    type="revolute">
    <origin
      xyz="0.0146 0.0205 0"
      rpy="1.5708 -2.9698E-15 -2.9101" />
    <parent
      link=" link1" />
    <child
      link="link2" />
    <axis
      xyz="0 -1 0" />
    <limit
      effort="0"
      velocity="0" />
  </joint>
  <link
    name="link3">
    <inertial>
      <origin
        xyz="0.0284085212669502 0.0351285785408569 -0.0179458094639415"
        rpy="0 0 0" />
      <mass
        value="0.0295644975322909" />
      <inertia
        ixx="1.33936846118549E-05"
        ixy="1.12377677320612E-07"
        ixz="-2.16441718720014E-05"
        iyy="8.67988836354431E-05"
        iyz="-3.78232802917669E-08"
        izz="8.06221951181824E-05" />
    </inertial>
    <visual>
      <origin
        xyz="0 0 0"
        rpy="0 0 0" />
      <geometry>
        <mesh
          filename="package://5DoF-arm-kenny/meshes/link3.STL" />
      </geometry>
      <material
        name="">
        <color
          rgba="0 1 1 1" />
      </material>
    </visual>
    <collision>
      <origin
        xyz="0 0 0"
        rpy="0 0 0" />
      <geometry>
        <mesh
          filename="package://5DoF-arm-kenny/meshes/link3.STL" />
      </geometry>
    </collision>
  </link>
  <joint
    name="j2"
    type="revolute">
    <origin
      xyz="0 0 0.14"
      rpy="3.1416 -0.93185 4.9195E-14" />
    <parent
      link="link2" />
    <child
      link="link3" />
    <axis
      xyz="0 1 0" />
    <limit
      effort="0"
      velocity="0" />
  </joint>
  <link
    name="link 4">
    <inertial>
      <origin
        xyz="-0.0173898278086403 -0.0350000000000029 0.0380464145686477"
        rpy="0 0 0" />
      <mass
        value="0.0057062055751799" />
      <inertia
        ixx="4.84737863927083E-06"
        ixy="8.43062480314046E-20"
        ixz="2.68203607851555E-07"
        iyy="2.30339791212611E-06"
        iyz="1.10802497412703E-19"
        izz="6.7343095380978E-06" />
    </inertial>
    <visual>
      <origin
        xyz="0 0 0"
        rpy="0 0 0" />
      <geometry>
        <mesh
          filename="package://5DoF-arm-kenny/meshes/link 4.STL" />
      </geometry>
      <material
        name="">
        <color
          rgba="0.792156862745098 0.819607843137255 0.933333333333333 1" />
      </material>
    </visual>
    <collision>
      <origin
        xyz="0 0 0"
        rpy="0 0 0" />
      <geometry>
        <mesh
          filename="package://5DoF-arm-kenny/meshes/link 4.STL" />
      </geometry>
    </collision>
  </link>
  <joint
    name="j3"
    type="revolute">
    <origin
      xyz="0.14 0 0"
      rpy="1.8459E-14 1.24 -3.1416" />
    <parent
      link="link3" />
    <child
      link="link 4" />
    <axis
      xyz="0 -1 0" />
    <limit
      effort="0"
      velocity="0" />
  </joint>
</robot>